Workbook

Sheet README
A1: Energy Security Index — Step 4: GDP per Capita (2024)
A2: Purpose | B2: Retain only countries with a numeric Step 3 score, rank those with usable 2024 GDP per capita data, and normalize GDP per capita logarithmically to 0–100.
A3: Step 3 eligibility rule | B3: A country is eligible only if it has a numeric value in Country Calc → Step 3 Score (0-100) in the BACI Step 3 workbook.
A4: GDP source rule | B4: Countries must also have a positive numeric GDP per capita value in the uploaded 2024 constant-2015-US$ World Bank source.
A5: Step 4 formula | B5: 100 × [ln(GDPpcᵢ) − ln(GDPpcₘᵢₙ)] / [ln(GDPpcₘₐₓ) − ln(GDPpcₘᵢₙ)]
A6: Ranking | B6: GDP per capita descending; rank 1 is the highest GDP per capita among Step 3-eligible countries with GDP data.
A7: Step 3-scored countries | B7: 197
A8: Countries with usable GDP data | B8: 188
A9: Step 3-scored countries missing GDP data | B9: 9
A10: GDP source file | B10: Step 4. GDP Per Capita 2024_2015USD.xls
A11: Step 3 source file | B11: Energy_Security_Index_Step3_BACI_2024.xlsx
A12: GDP indicator | B12: GDP per capita (constant 2015 US$)
A13: Important | B13: The min and max used in the formula are calculated only from the retained Step 3-eligible countries with usable GDP data, not from the entire World Bank file.

Sheet Parameters
A1: Parameter | B1: Value | C1: Notes
A2: Eligible country count | B2: =COUNT('GDP Source - Filtered'!D2:D189) -> 188 | C2: Count of countries in filtered GDP source
A3: GDPpc minimum | B3: =MIN('GDP Source - Filtered'!D2:D189) -> 268.70086 | C3: Minimum among retained countries
A4: GDPpc maximum | B4: =MAX('GDP Source - Filtered'!D2:D189) -> 116513.54 | C4: Maximum among retained countries
A5: ln(GDPpc minimum) | B5: =LN(B3) -> 5.5935987 | C5: Natural log of eligible minimum
A6: ln(GDPpc maximum) | B6: =LN(B4) -> 11.665763 | C6: Natural log of eligible maximum

Sheet Step 3 Eligibility
A1: ISO3 | B1: Step 3 Country | C1: Step 3 Score (0-100) | D1: GDP Source Country | E1: GDP per Capita (constant 2015 US$) | F1: Included in Step 4 | G1: Exclusion Reason
A2: AFG | B2: Afghanistan | C2: 36.04924 | D2: Afghanistan | E2: 374.3767 | F2: Yes
A3: ALB | B3: Albania | C3: 84.115138 | D3: Albania | E3: 6549.2339 | F3: Yes
A4: DZA | B4: Algeria | C4: 100 | D4: Algeria | E4: 4765.729 | F4: Yes
A5: ASM | B5: American Samoa | C5: 33.562521 | F5: No | G5: No usable 2024 GDP per capita value in uploaded Step 4 source
A6: AGO | B6: Angola | C6: 100 | D6: Angola | E6: 2798.5939 | F6: Yes
A7: ATG | B7: Antigua and Barbuda | C7: 32.82094 | D7: Antigua and Barbuda | E7: 18304.584 | F7: Yes
A8: ARG | B8: Argentina | C8: 100 | D8: Argentina | E8: 12774.351 | F8: Yes
A9: ARM | B9: Armenia | C9: 42.592748 | D9: Armenia | E9: 5378.318 | F9: Yes
A10: ABW | B10: Aruba | C10: 28.305691 | D10: Aruba | E10: 33938.954 | F10: Yes
A11: AUS | B11: Australia | C11: 100 | D11: Australia | E11: 61486.381 | F11: Yes
A12: AUT | B12: Austria | C12: 54.875246 | D12: Austria | E12: 45958.825 | F12: Yes
A13: AZE | B13: Azerbaijan | C13: 100 | D13: Azerbaijan | E13: 5876.033 | F13: Yes
A14: BHS | B14: Bahamas | C14: 34.293393 | D14: Bahamas, The | E14: 33968.203 | F14: Yes
A15: BHR | B15: Bahrain | C15: 100 | D15: Bahrain | E15: 25886.239 | F15: Yes
A16: BGD | B16: Bangladesh | C16: 59.301519 | D16: Bangladesh | E16: 1941.2787 | F16: Yes
A17: BRB | B17: Barbados | C17: 42.742087 | D17: Barbados | E17: 22421.533 | F17: Yes
... A51: CIV | B51: CÃ´te d'Ivoire | C51: 75.164047 | D51: Cote d'Ivoire | E51: 2395.6592 | F51: Yes
A52: PRK | B52: Dem. People's Rep. of Korea | C52: 95.093428 | F52: No | G52: No usable 2024 GDP per capita value in uploaded Step 4 source
A53: COD | B53: Dem. Rep. of the Congo | C53: 84.5314 | D53: Congo, Dem. Rep. | E53: 554.11761 | F53: Yes
A54: DNK | B54: Denmark | C54: 76.616861 | D54: Denmark | E54: 60772.862 | F54: Yes
A55: DJI | B55: Djibouti | C55: 23.957504 | D55: Djibouti | E55: 3290.4248 | F55: Yes
A56: DMA | B56: Dominica | C56: 33.725148 | D56: Dominica | E56: 9172.7105 | F56: Yes
A57: DOM | B57: Dominican Rep. | C57: 31.345941 | D57: Dominican Republic | E57: 9168.4542 | F57: Yes
A58: ECU | B58: Ecuador | C58: 100 | D58: Ecuador | E58: 5993.747 | F58: Yes
A59: EGY | B59: Egypt | C59: 82.514993 | D59: Egypt, Arab Rep. | E59: 4137.6093 | F59: Yes
A60: SLV | B60: El Salvador | C60: 38.185357 | D60: El Salvador | E60: 4576.5585 | F60: Yes
A61: GNQ | B61: Equatorial Guinea | C61: 100 | D61: Equatorial Guinea | E61: 4892.9531 | F61: Yes
A62: ERI | B62: Eritrea | C62: 31.280866 | F62: No | G62: No usable 2024 GDP per capita value in uploaded Step 4 source
A63: EST | B63: Estonia | C63: 51.720573 | D63: Estonia | E63: 20078.14 | F63: Yes
A64: SWZ | B64: Eswatini | C64: 59.329805 | D64: Eswatini | E64: 3866.3713 | F64: Yes
A65: ETH | B65: Ethiopia | C65: 48.244985 | D65: Ethiopia | E65: 883.45859 | F65: Yes
A66: FSM | B66: FS Micronesia | C66: 40.228422 | D66: Micronesia, Fed. Sts. | E66: 3001.7967 | F66: Yes
A67: FJI | B67: Fiji | C67: 38.389235 | D67: Fiji | E67: 5935.209 | F67: Yes
A68: FIN | B68: Finland | C68: 71.706223 | D68: Finland | E68: 45075.168 | F68: Yes
A69: FRA | B69: France | C69: 69.602677 | D69: France | E69: 39683.395 | F69: Yes
A70: PYF | B70: French Polynesia | C70: 40.321337 | D70: French Polynesia | E70: 20846.651 | F70: Yes
A71: GAB | B71: Gabon | C71: 100 | D71: Gabon | E71: 6618.9869 | F71: Yes
A72: GMB | B72: Gambia | C72: 34.978164 | D72: Gambia, The | E72: 758.96589 | F72: Yes
A73: GEO | B73: Georgia | C73: 44.985933 | D73: Georgia | E73: 6606.3577 | F73: Yes
...

Sheet GDP Source - Filtered
A1: GDP Source Country | B1: ISO3 | C1: Indicator | D1: GDP per Capita (constant 2015 US$) | E1: Step 3 Country | F1: Step 3 Score (0-100)
A2: Bermuda | B2: BMU | C2: GDP per capita (constant 2015 US$) | D2: 116513.54 | E2: Bermuda | F2: 34.836383
A3: Luxembourg | B3: LUX | C3: GDP per capita (constant 2015 US$) | D3: 104147.11 | E3: Luxembourg | F3: 36.846598
A4: Ireland | B4: IRL | C4: GDP per capita (constant 2015 US$) | D4: 94474.988 | E4: Ireland | F4: 47.624737
A5: Switzerland | B5: CHE | C5: GDP per capita (constant 2015 US$) | D5: 93018.377 | E5: Switzerland | F5: 67.947704
A6: Cayman Islands | B6: CYM | C6: GDP per capita (constant 2015 US$) | D6: 84381.473 | E6: Cayman Isds | F6: 28.71295
A7: Norway | B7: NOR | C7: GDP per capita (constant 2015 US$) | D7: 83487.133 | E7: Norway | F7: 100
A8: Singapore | B8: SGP | C8: GDP per capita (constant 2015 US$) | D8: 68129.696 | E8: Singapore | F8: 42.292658
A9: United States | B9: USA | C9: GDP per capita (constant 2015 US$) | D9: 66856.513 | E9: USA | F9: 100
A10: Macao SAR, China | B10: MAC | C10: GDP per capita (constant 2015 US$) | D10: 63377.293 | E10: China, Macao SAR | F10: 26.096174
A11: Qatar | B11: QAT | C11: GDP per capita (constant 2015 US$) | D11: 62395.311 | E11: Qatar | F11: 100
A12: Australia | B12: AUS | C12: GDP per capita (constant 2015 US$) | D12: 61486.381 | E12: Australia | F12: 100
A13: Denmark | B13: DNK | C13: GDP per capita (constant 2015 US$) | D13: 60772.862 | E13: Denmark | F13: 76.616861
... A189: Burundi | B189: BDI | C189: GDP per capita (constant 2015 US$) | D189: 268.70086 | E189: Burundi | F189: 35.941092

Sheet Step 4 Results
A1: GDPpc Rank | B1: Country | C1: ISO3 | D1: GDP per Capita (constant 2015 US$) | E1: ln(GDPpcᵢ) | F1: ln(GDPpcₘᵢₙ) | G1: ln(GDPpcₘₐₓ) | H1: Step 4 Score (0-100) | I1: Step 3 Score (0-100) | J1: GDP Source Country
A2: =ROW()-1 -> 1 | B2: ='GDP Source - Filtered'!E2 -> Bermuda | C2: ='GDP Source - Filtered'!B2 -> BMU | D2: ='GDP Source - Filtered'!D2 -> 116513.54 | E2: =LN(D2) -> 11.665763 | F2: =Parameters!$B$5 -> 5.5935987 | G2: =Parameters!$B$6 -> 11.665763 | H2: =100*(E2-F2)/(G2-F2) -> 100 | I2: ='GDP Source - Filtered'!F2 -> 34.836383 | J2: ='GDP Source - Filtered'!A2 -> Bermuda
A3: =ROW()-1 -> 2 | B3: ='GDP Source - Filtered'!E3 -> Luxembourg | C3: ='GDP Source - Filtered'!B3 -> LUX | D3: ='GDP Source - Filtered'!D3 -> 104147.11 | E3: =LN(D3) -> 11.55356 | F3: =Parameters!$B$5 -> 5.5935987 | G3: =Parameters!$B$6 -> 11.665763 | H3: =100*(E3-F3)/(G3-F3) -> 98.152174 | I3: ='GDP Source - Filtered'!F3 -> 36.846598 | J3: ='GDP Source - Filtered'!A3 -> Luxembourg
A4: =ROW()-1 -> 3 | B4: ='GDP Source - Filtered'!E4 -> Ireland | C4: ='GDP Source - Filtered'!B4 -> IRL | D4: ='GDP Source - Filtered'!D4 -> 94474.988 | E4: =LN(D4) -> 11.45609 | F4: =Parameters!$B$5 -> 5.5935987 | G4: =Parameters!$B$6 -> 11.665763 | H4: =100*(E4-F4)/(G4-F4) -> 96.546992 | I4: ='GDP Source - Filtered'!F4 -> 47.624737 | J4: ='GDP Source - Filtered'!A4 -> Ireland
A5: =ROW()-1 -> 4 | B5: ='GDP Source - Filtered'!E5 -> Switzerland | C5: ='GDP Source - Filtered'!B5 -> CHE | D5: ='GDP Source - Filtered'!D5 -> 93018.377 | E5: =LN(D5) -> 11.440552 | F5: =Parameters!$B$5 -> 5.5935987 | G5: =Parameters!$B$6 -> 11.665763 | H5: =100*(E5-F5)/(G5-F5) -> 96.291102 | I5: ='GDP Source - Filtered'!F5 -> 67.947704 | J5: ='GDP Source - Filtered'!A5 -> Switzerland
A6: =ROW()-1 -> 5 | B6: ='GDP Source - Filtered'!E6 -> Cayman Isds | C6: ='GDP Source - Filtered'!B6 -> CYM | D6: ='GDP Source - Filtered'!D6 -> 84381.473 | E6: =LN(D6) -> 11.343103 | F6: =Parameters!$B$5 -> 5.5935987 | G6: =Parameters!$B$6 -> 11.665763 | H6: =100*(E6-F6)/(G6-F6) -> 94.68625 | I6: ='GDP Source - Filtered'!F6 -> 28.71295 | J6: ='GDP Source - Filtered'!A6 -> Cayman Islands
A7: =ROW()-1 -> 6 | B7: ='GDP Source - Filtered'!E7 -> Norway | C7: ='GDP Source - Filtered'!B7 -> NOR | D7: ='GDP Source - Filtered'!D7 -> 83487.133 | E7: =LN(D7) -> 11.332448 | F7: =Parameters!$B$5 -> 5.5935987 | G7: =Parameters!$B$6 -> 11.665763 | H7: =100*(E7-F7)/(G7-F7) -> 94.510772 | I7: ='GDP Source - Filtered'!F7 -> 100 | J7: ='GDP Source - Filtered'!A7 -> Norway
A8: =ROW()-1 -> 7 | B8: ='GDP Source - Filtered'!E8 -> Singapore | C8: ='GDP Source - Filtered'!B8 -> SGP | D8: ='GDP Source - Filtered'!D8 -> 68129.696 | E8: =LN(D8) -> 11.129168 | F8: =Parameters!$B$5 -> 5.5935987 | G8: =Parameters!$B$6 -> 11.665763 | H8: =100*(E8-F8)/(G8-F8) -> 91.163047 | I8: ='GDP Source - Filtered'!F8 -> 42.292658 | J8: ='GDP Source - Filtered'!A8 -> Singapore
A9: =ROW()-1 -> 8 | B9: ='GDP Source - Filtered'!E9 -> USA | C9: ='GDP Source - Filtered'!B9 -> USA | D9: ='GDP Source - Filtered'!D9 -> 66856.513 | E9: =LN(D9) -> 11.110304 | F9: =Parameters!$B$5 -> 5.5935987 | G9: =Parameters!$B$6 -> 11.665763 | H9: =100*(E9-F9)/(G9-F9) -> 90.852376 | I9: ='GDP Source - Filtered'!F9 -> 100 | J9: ='GDP Source - Filtered'!A9 -> United States
A10: =ROW()-1 -> 9 | B10: ='GDP Source - Filtered'!E10 -> China, Macao SAR | C10: ='GDP Source - Filtered'!B10 -> MAC | D10: ='GDP Source - Filtered'!D10 -> 63377.293 | E10: =LN(D10) -> 11.056861 | F10: =Parameters!$B$5 -> 5.5935987 | G10: =Parameters!$B$6 -> 11.665763 | H10: =100*(E10-F10)/(G10-F10) -> 89.972244 | I10: ='GDP Source - Filtered'!F10 -> 26.096174 | J10: ='GDP Source - Filtered'!A10 -> Macao SAR, China
A11: =ROW()-1 -> 10 | B11: ='GDP Source - Filtered'!E11 -> Qatar | C11: ='GDP Source - Filtered'!B11 -> QAT | D11: ='GDP Source - Filtered'!D11 -> 62395.311 | E11: =LN(D11) -> 11.041245 | F11: =Parameters!$B$5 -> 5.5935987 | G11: =Parameters!$B$6 -> 11.665763 | H11: =100*(E11-F11)/(G11-F11) -> 89.715078 | I11: ='GDP Source - Filtered'!F11 -> 100 | J11: ='GDP Source - Filtered'!A11 -> Qatar
A12: =ROW()-1 -> 11 | B12: ='GDP Source - Filtered'!E12 -> Australia | C12: ='GDP Source - Filtered'!B12 -> AUS | D12: ='GDP Source - Filtered'!D12 -> 61486.381 | E12: =LN(D12) -> 11.026571 | F12: =Parameters!$B$5 -> 5.5935987 | G12: =Parameters!$B$6 -> 11.665763 | H12: =100*(E12-F12)/(G12-F12) -> 89.473411 | I12: ='GDP Source - Filtered'!F12 -> 100 | J12: ='GDP Source - Filtered'!A12 -> Australia
A13: =ROW()-1 -> 12 | B13: ='GDP Source - Filtered'!E13 -> Denmark | C13: ='GDP Source - Filtered'!B13 -> DNK | D13: ='GDP Source - Filtered'!D13 -> 60772.862 | E13: =LN(D13) -> 11.014899 | F13: =Parameters!$B$5 -> 5.5935987 | G13: =Parameters!$B$6 -> 11.665763 | H13: =100*(E13-F13)/(G13-F13) -> 89.281184 | I13: ='GDP Source - Filtered'!F13 -> 76.616861 | J13: ='GDP Source - Filtered'!A13 -> Denmark
... A189: =ROW()-1 -> 188 | B189: ='GDP Source - Filtered'!E189 -> Burundi | C189: ='GDP Source - Filtered'!B189 -> BDI | D189: ='GDP Source - Filtered'!D189 -> 268.70086 | E189: =LN(D189) -> 5.5935987 | F189: =Parameters!$B$5 -> 5.5935987 | G189: =Parameters!$B$6 -> 11.665763 | H189: =100*(E189-F189)/(G189-F189) -> 0 | I189: ='GDP Source - Filtered'!F189 -> 35.941092 | J189: ='GDP Source - Filtered'!A189 -> Burundi
